Workbook

Sheet Startup_Summary
A1: Final Rank | B1: Startup | C1: Category | D1: Founded | E1: HQ | F1: Total funding (USD M) | G1: Employees | H1: WIPO query used | I1: Result count on WIPO page | J1: Rows downloaded | K1: Matched patent records | L1: Rows rejected (unrelated applicant) | M1: Unique publication numbers | N1: First publication year | O1: Last publication year | P1: Records: IN office | Q1: Records: WO (PCT) | R1: Records: other offices | S1: Search outcome / notes
A2: 1 | B2: Ola Electric | C2: EV & charging | D2: 2017 | E2: Bengaluru | F2: 1500 | G2: 8996 | H2: PA:("Ola Electric") | I2: 271 | J2: 271 | K2: =COUNTIF(Patents_Merged!$A$2:$A$731,B2) -> 269 | L2: =J2-K2 -> 2 | M2: =IFERROR(SUMPRODUCT((Patents_Merged!$A$2:$A$731=B2)/COUNTIFS(Patents_Merged!$A$2:$A$731,Patents_Merged!$A$2:$A$731,Patents_Merged!$G$2:$G$731,Patents_Merged!$G$2:$G$731)),0) -> 269 | N2: =IF(K2=0,"",9999-SUMPRODUCT(MAX((Patents_Merged!$A$2:$A$731=B2)*(9999-Patents_Merged!$I$2:$I$731)))) -> 2021 | O2: =IF(K2=0,"",SUMPRODUCT(MAX((Patents_Merged!$A$2:$A$731=B2)*Patents_Merged!$I$2:$I$731))) -> 2026 | P2: =COUNTIFS(Patents_Merged!$A$2:$A$731,B2,Patents_Merged!$J$2:$J$731,"IN") -> 123 | Q2: =COUNTIFS(Patents_Merged!$A$2:$A$731,B2,Patents_Merged!$J$2:$J$731,"WO") -> 116 | R2: =K2-P2-Q2 -> 30 | S2: Records found and matched.
A3: 2 | B3: ACME Solar | C3: Solar & clean energy | D3: 2003 | E3: Gurugram (verify) | F3: 1250 | G3: 3158 | H3: PA:("ACME Solar Holdings Ltd"); PA:("ACME Group") | I3: 0 | J3: 0 | K3: =COUNTIF(Patents_Merged!$A$2:$A$731,B3) -> 0 | L3: =J3-K3 -> 0 | M3: =IFERROR(SUMPRODUCT((Patents_Merged!$A$2:$A$731=B3)/COUNTIFS(Patents_Merged!$A$2:$A$731,Patents_Merged!$A$2:$A$731,Patents_Merged!$G$2:$G$731,Patents_Merged!$G$2:$G$731)),0) -> 0 | N3: =IF(K3=0,"",9999-SUMPRODUCT(MAX((Patents_Merged!$A$2:$A$731=B3)*(9999-Patents_Merged!$I$2:$I$731)))) | O3: =IF(K3=0,"",SUMPRODUCT(MAX((Patents_Merged!$A$2:$A$731=B3)*Patents_Merged!$I$2:$I$731))) | P3: =COUNTIFS(Patents_Merged!$A$2:$A$731,B3,Patents_Merged!$J$2:$J$731,"IN") -> 0 | Q3: =COUNTIFS(Patents_Merged!$A$2:$A$731,B3,Patents_Merged!$J$2:$J$731,"WO") -> 0 | R3: =K3-P3-Q3 -> 0 | S3: 0 relevant results. Group query returned US firms (fire suppression etc.). Try PA:("ACME Solar") once if not done.
A4: 3 | B4: Ather Energy | C4: EV & charging | D4: 2013 | E4: Bengaluru | F4: 574.27 | G4: 4544 | H4: PA:("Ather Energy") | I4: 100 | J4: 100 | K4: =COUNTIF(Patents_Merged!$A$2:$A$731,B4) -> 100 | L4: =J4-K4 -> 0 | M4: =IFERROR(SUMPRODUCT((Patents_Merged!$A$2:$A$731=B4)/COUNTIFS(Patents_Merged!$A$2:$A$731,Patents_Merged!$A$2:$A$731,Patents_Merged!$G$2:$G$731,Patents_Merged!$G$2:$G$731)),0) -> 100 | N4: =IF(K4=0,"",9999-SUMPRODUCT(MAX((Patents_Merged!$A$2:$A$731=B4)*(9999-Patents_Merged!$I$2:$I$731)))) -> 2017 | O4: =IF(K4=0,"",SUMPRODUCT(MAX((Patents_Merged!$A$2:$A$731=B4)*Patents_Merged!$I$2:$I$731))) -> 2026 | P4: =COUNTIFS(Patents_Merged!$A$2:$A$731,B4,Patents_Merged!$J$2:$J$731,"IN") -> 56 | Q4: =COUNTIFS(Patents_Merged!$A$2:$A$731,B4,Patents_Merged!$J$2:$J$731,"WO") -> 37 | R4: =K4-P4-Q4 -> 7 | S4: Records found and matched.
A5: 4 | B5: Euler Motors | C5: EV & charging | D5: 2018 | E5: New Delhi | F5: 376.94 | G5: 1588 | H5: PA:("Euler Motors") | I5: 0 | J5: 0 | K5: =COUNTIF(Patents_Merged!$A$2:$A$731,B5) -> 0 | L5: =J5-K5 -> 0 | M5: =IFERROR(SUMPRODUCT((Patents_Merged!$A$2:$A$731=B5)/COUNTIFS(Patents_Merged!$A$2:$A$731,Patents_Merged!$A$2:$A$731,Patents_Merged!$G$2:$G$731,Patents_Merged!$G$2:$G$731)),0) -> 0 | N5: =IF(K5=0,"",9999-SUMPRODUCT(MAX((Patents_Merged!$A$2:$A$731=B5)*(9999-Patents_Merged!$I$2:$I$731)))) | O5: =IF(K5=0,"",SUMPRODUCT(MAX((Patents_Merged!$A$2:$A$731=B5)*Patents_Merged!$I$2:$I$731))) | P5: =COUNTIFS(Patents_Merged!$A$2:$A$731,B5,Patents_Merged!$J$2:$J$731,"IN") -> 0 | Q5: =COUNTIFS(Patents_Merged!$A$2:$A$731,B5,Patents_Merged!$J$2:$J$731,"WO") -> 0 | R5: =K5-P5-Q5 -> 0 | S5: 0 results. Valid zero; confirm spelling Euler and any variant tried.
A6: 5 | B6: Battery Smart | C6: EV & charging | D6: 2019 | E6: New Delhi | F6: 228.09 | G6: 1155 | H6: PA:("Battery Smart") | I6: 0 | J6: 0 | K6: =COUNTIF(Patents_Merged!$A$2:$A$731,B6) -> 0 | L6: =J6-K6 -> 0 | M6: =IFERROR(SUMPRODUCT((Patents_Merged!$A$2:$A$731=B6)/COUNTIFS(Patents_Merged!$A$2:$A$731,Patents_Merged!$A$2:$A$731,Patents_Merged!$G$2:$G$731,Patents_Merged!$G$2:$G$731)),0) -> 0 | N6: =IF(K6=0,"",9999-SUMPRODUCT(MAX((Patents_Merged!$A$2:$A$731=B6)*(9999-Patents_Merged!$I$2:$I$731)))) | O6: =IF(K6=0,"",SUMPRODUCT(MAX((Patents_Merged!$A$2:$A$731=B6)*Patents_Merged!$I$2:$I$731))) | P6: =COUNTIFS(Patents_Merged!$A$2:$A$731,B6,Patents_Merged!$J$2:$J$731,"IN") -> 0 | Q6: =COUNTIFS(Patents_Merged!$A$2:$A$731,B6,Patents_Merged!$J$2:$J$731,"WO") -> 0 | R6: =K6-P6-Q6 -> 0 | S6: PA:(Battery Smart), which gave 38 unrelated hits, and PA:("Battery Smart"),
A7: 6 | B7: Simple Energy | C7: EV & charging | D7: 2019 | E7: Bengaluru | F7: 290.5 | G7: 673 | H7: PA:("Simple Energy"); PA:("Simple Energy Private Limited") | I7: 0 | J7: 0 | K7: =COUNTIF(Patents_Merged!$A$2:$A$731,B7) -> 0 | L7: =J7-K7 -> 0 | M7: =IFERROR(SUMPRODUCT((Patents_Merged!$A$2:$A$731=B7)/COUNTIFS(Patents_Merged!$A$2:$A$731,Patents_Merged!$A$2:$A$731,Patents_Merged!$G$2:$G$731,Patents_Merged!$G$2:$G$731)),0) -> 0 | N7: =IF(K7=0,"",9999-SUMPRODUCT(MAX((Patents_Merged!$A$2:$A$731=B7)*(9999-Patents_Merged!$I$2:$I$731)))) | O7: =IF(K7=0,"",SUMPRODUCT(MAX((Patents_Merged!$A$2:$A$731=B7)*Patents_Merged!$I$2:$I$731))) | P7: =COUNTIFS(Patents_Merged!$A$2:$A$731,B7,Patents_Merged!$J$2:$J$731,"IN") -> 0 | Q7: =COUNTIFS(Patents_Merged!$A$2:$A$731,B7,Patents_Merged!$J$2:$J$731,"WO") -> 0 | R7: =K7-P7-Q7 -> 0 | S7: PA:("Simple Energy") with 12 results, all unrelated (a UK and a US company with the same name), and PA:("Simple Energy Private Limited") with 0 results Date: 19.10.2026
A8: 7 | B8: River | C8: EV & charging | D8: 2020 | E8: Bengaluru | F8: 188 | G8: 1174 | H8: PA:("River mobility") | I8: 20 | J8: 20 | K8: =COUNTIF(Patents_Merged!$A$2:$A$731,B8) -> 20 | L8: =J8-K8 -> 0 | M8: =IFERROR(SUMPRODUCT((Patents_Merged!$A$2:$A$731=B8)/COUNTIFS(Patents_Merged!$A$2:$A$731,Patents_Merged!$A$2:$A$731,Patents_Merged!$G$2:$G$731,Patents_Merged!$G$2:$G$731)),0) -> 20 | N8: =IF(K8=0,"",9999-SUMPRODUCT(MAX((Patents_Merged!$A$2:$A$731=B8)*(9999-Patents_Merged!$I$2:$I$731)))) -> 2022 | O8: =IF(K8=0,"",SUMPRODUCT(MAX((Patents_Merged!$A$2:$A$731=B8)*Patents_Merged!$I$2:$I$731))) -> 2023 | P8: =COUNTIFS(Patents_Merged!$A$2:$A$731,B8,Patents_Merged!$J$2:$J$731,"IN") -> 20 | Q8: =COUNTIFS(Patents_Merged!$A$2:$A$731,B8,Patents_Merged!$J$2:$J$731,"WO") -> 0 | R8: =K8-P8-Q8 -> 0 | S8: Records found and matched.
A9: 8 | B9: SolarSquare | C9: Solar & clean energy | D9: 2015 | E9: Mumbai | F9: 113.25 | G9: 2924 | H9: PA:("SolarSquare");PA:("Solar Square") and PA:("SolarSquare Energy") | I9: 0 | J9: 0 | K9: =COUNTIF(Patents_Merged!$A$2:$A$731,B9) -> 0 | L9: =J9-K9 -> 0 | M9: =IFERROR(SUMPRODUCT((Patents_Merged!$A$2:$A$731=B9)/COUNTIFS(Patents_Merged!$A$2:$A$731,Patents_Merged!$A$2:$A$731,Patents_Merged!$G$2:$G$731,Patents_Merged!$G$2:$G$731)),0) -> 0 | N9: =IF(K9=0,"",9999-SUMPRODUCT(MAX((Patents_Merged!$A$2:$A$731=B9)*(9999-Patents_Merged!$I$2:$I$731)))) | O9: =IF(K9=0,"",SUMPRODUCT(MAX((Patents_Merged!$A$2:$A$731=B9)*Patents_Merged!$I$2:$I$731))) | P9: =COUNTIFS(Patents_Merged!$A$2:$A$731,B9,Patents_Merged!$J$2:$J$731,"IN") -> 0 | Q9: =COUNTIFS(Patents_Merged!$A$2:$A$731,B9,Patents_Merged!$J$2:$J$731,"WO") -> 0 | R9: =K9-P9-Q9 -> 0 | S9: PA:("SolarSquare"), PA:("Solar Square") and PA:("SolarSquare Energy")
A10: 9 | B10: Bounce | C10: EV & charging | D10: 2014 | E10: Bengaluru | F10: 238.06 | G10: 637 | H10: PA:("Bounce") | I10: 0 | J10: 0 | K10: =COUNTIF(Patents_Merged!$A$2:$A$731,B10) -> 0 | L10: =J10-K10 -> 0 | M10: =IFERROR(SUMPRODUCT((Patents_Merged!$A$2:$A$731=B10)/COUNTIFS(Patents_Merged!$A$2:$A$731,Patents_Merged!$A$2:$A$731,Patents_Merged!$G$2:$G$731,Patents_Merged!$G$2:$G$731)),0) -> 0 | N10: =IF(K10=0,"",9999-SUMPRODUCT(MAX((Patents_Merged!$A$2:$A$731=B10)*(9999-Patents_Merged!$I$2:$I$731)))) | O10: =IF(K10=0,"",SUMPRODUCT(MAX((Patents_Merged!$A$2:$A$731=B10)*Patents_Merged!$I$2:$I$731))) | P10: =COUNTIFS(Patents_Merged!$A$2:$A$731,B10,Patents_Merged!$J$2:$J$731,"IN") -> 0 | Q10: =COUNTIFS(Patents_Merged!$A$2:$A$731,B10,Patents_Merged!$J$2:$J$731,"WO") -> 0 | R10: =K10-P10-Q10 -> 0 | S10: PA:("Bounce") with 176 unrelated hits, plus the three variants above
A11: 10 | B11: SUN Mobility | C11: EV & charging | D11: 2017 | E11: Bengaluru | F11: 135 | G11: 959 | H11: PA:("SUN Mobility") | I11: 87 | J11: 87 | K11: =COUNTIF(Patents_Merged!$A$2:$A$731,B11) -> 87 | L11: =J11-K11 -> 0 | M11: =IFERROR(SUMPRODUCT((Patents_Merged!$A$2:$A$731=B11)/COUNTIFS(Patents_Merged!$A$2:$A$731,Patents_Merged!$A$2:$A$731,Patents_Merged!$G$2:$G$731,Patents_Merged!$G$2:$G$731)),0) -> 87 | N11: =IF(K11=0,"",9999-SUMPRODUCT(MAX((Patents_Merged!$A$2:$A$731=B11)*(9999-Patents_Merged!$I$2:$I$731)))) -> 2018 | O11: =IF(K11=0,"",SUMPRODUCT(MAX((Patents_Merged!$A$2:$A$731=B11)*Patents_Merged!$I$2:$I$731))) -> 2026 | P11: =COUNTIFS(Patents_Merged!$A$2:$A$731,B11,Patents_Merged!$J$2:$J$731,"IN") -> 7 | Q11: =COUNTIFS(Patents_Merged!$A$2:$A$731,B11,Patents_Merged!$J$2:$J$731,"WO") -> 54 | R11: =K11-P11-Q11 -> 26 | S11: Records found and matched.
A12: 11 | B12: Ultraviolette Automotive | C12: EV & charging | D12: 2016 | E12: Bengaluru | F12: 220.9 | G12: 586 | H12: PA:("Ultraviolette Automotive") | I12: 43 | J12: 43 | K12: =COUNTIF(Patents_Merged!$A$2:$A$731,B12) -> 43 | L12: =J12-K12 -> 0 | M12: =IFERROR(SUMPRODUCT((Patents_Merged!$A$2:$A$731=B12)/COUNTIFS(Patents_Merged!$A$2:$A$731,Patents_Merged!$A$2:$A$731,Patents_Merged!$G$2:$G$731,Patents_Merged!$G$2:$G$731)),0) -> 43 | N12: =IF(K12=0,"",9999-SUMPRODUCT(MAX((Patents_Merged!$A$2:$A$731=B12)*(9999-Patents_Merged!$I$2:$I$731)))) -> 2018 | O12: =IF(K12=0,"",SUMPRODUCT(MAX((Patents_Merged!$A$2:$A$731=B12)*Patents_Merged!$I$2:$I$731))) -> 2024 | P12: =COUNTIFS(Patents_Merged!$A$2:$A$731,B12,Patents_Merged!$J$2:$J$731,"IN") -> 37 | Q12: =COUNTIFS(Patents_Merged!$A$2:$A$731,B12,Patents_Merged!$J$2:$J$731,"WO") -> 6 | R12: =K12-P12-Q12 -> 0 | S12: Records found and matched.
A13: 12 | B13: Agratas | C13: Energy storage | D13: 2023 | E13: Bengaluru (verify) | F13: 113.14 | G13: 901 | H13: PA:("Agratas"); PA:("Agratas Energy Storage") | I13: 0 | J13: 0 | K13: =COUNTIF(Patents_Merged!$A$2:$A$731,B13) -> 0 | L13: =J13-K13 -> 0 | M13: =IFERROR(SUMPRODUCT((Patents_Merged!$A$2:$A$731=B13)/COUNTIFS(Patents_Merged!$A$2:$A$731,Patents_Merged!$A$2:$A$731,Patents_Merged!$G$2:$G$731,Patents_Merged!$G$2:$G$731)),0) -> 0 | N13: =IF(K13=0,"",9999-SUMPRODUCT(MAX((Patents_Merged!$A$2:$A$731=B13)*(9999-Patents_Merged!$I$2:$I$731)))) | O13: =IF(K13=0,"",SUMPRODUCT(MAX((Patents_Merged!$A$2:$A$731=B13)*Patents_Merged!$I$2:$I$731))) | P13: =COUNTIFS(Patents_Merged!$A$2:$A$731,B13,Patents_Merged!$J$2:$J$731,"IN") -> 0 | Q13: =COUNTIFS(Patents_Merged!$A$2:$A$731,B13,Patents_Merged!$J$2:$J$731,"WO") -> 0 | R13: =K13-P13-Q13 -> 0 | S13: founded 2023, so filings may not be published yet; any filings may also sit under a Tata group entity
... A21: 20 | B21: ChargeZone | C21: EV & charging | D21: 2018 | E21: Vadodara | F21: 86.11 | G21: 213 | H21: PA:("ChargeZone"); PA:("Charge Zone") | I21: 0 | J21: 0 | K21: =COUNTIF(Patents_Merged!$A$2:$A$731,B21) -> 0 | L21: =J21-K21 -> 0 | M21: =IFERROR(SUMPRODUCT((Patents_Merged!$A$2:$A$731=B21)/COUNTIFS(Patents_Merged!$A$2:$A$731,Patents_Merged!$A$2:$A$731,Patents_Merged!$G$2:$G$731,Patents_Merged!$G$2:$G$731)),0) -> 0 | N21: =IF(K21=0,"",9999-SUMPRODUCT(MAX((Patents_Merged!$A$2:$A$731=B21)*(9999-Patents_Merged!$I$2:$I$731)))) | O21: =IF(K21=0,"",SUMPRODUCT(MAX((Patents_Merged!$A$2:$A$731=B21)*Patents_Merged!$I$2:$I$731))) | P21: =COUNTIFS(Patents_Merged!$A$2:$A$731,B21,Patents_Merged!$J$2:$J$731,"IN") -> 0 | Q21: =COUNTIFS(Patents_Merged!$A$2:$A$731,B21,Patents_Merged!$J$2:$J$731,"WO") -> 0 | R21: =K21-P21-Q21 -> 0 | S21: a charging-network operator that may file few patents, or file under a different legal entity
B22: Total | J22: =SUM(J2:J21) -> 732 | K22: =SUM(K2:K21) -> 730 | L22: =SUM(L2:L21) -> 2 | P22: =SUM(P2:P21) -> 321 | Q22: =SUM(Q2:Q21) -> 260 | R22: =SUM(R2:R21) -> 149

Sheet Patents_Merged
A1: Startup | B1: Source file | C1: Query | D1: Application Id | E1: Application Number | F1: Application Date | G1: Publication Number | H1: Publication Date | I1: Publication year | J1: Country | K1: Title | L1: IPC | M1: Applicants (as in WIPO) | N1: Matched party | O1: Match method | P1: Match score | Q1: Other parties on filing | R1: Review flag | S1: Export time
A2: Ola Electric | B2: 01_Ola_Electric_raw.xls | C2: PA:("Ola Electric") | D2: US316418454 | E2: 16935765 | F2: 22.07.2020 | G2: 20210027334 | H2: 28.01.2021 | I2: 2021 | J2: US | K2: Vehicle Communication System | L2: G06Q 30/02; H04W 4/021; H04W 4/48; H04W 4/90; G06Q 50/30; G09F 21/04; G09F 27/00 | M2: OLA ELECTRIC MOBILITY PRIVATE LIMITED | N2: OLA ELECTRIC MOBILITY PRIVATE LIMITED | O2: exact-normalised | P2: 1 | S2: 19.10.2026 06:24:45
A3: Ola Electric | B3: 01_Ola_Electric_raw.xls | C3: PA:("Ola Electric") | D3: US316418529 | E3: 16935524 | F3: 22.07.2020 | G3: 20210027409 | H3: 28.01.2021 | I3: 2021 | J3: US | K3: Methods and Systems for Facilitating Safety and Security of Users | L3: G06Q 50/26; G06Q 50/00; G06Q 50/30; G06Q 30/02; H04W 4/90; H04W 4/40; G10L 15/08; G10L 15/22; H04N 5/232; B60R 21/01 | M3: OLA ELECTRIC MOBILITY PRIVATE LIMITED | N3: OLA ELECTRIC MOBILITY PRIVATE LIMITED | O3: exact-normalised | P3: 1 | S3: 19.10.2026 06:24:45
A4: Ola Electric | B4: 01_Ola_Electric_raw.xls | C4: PA:("Ola Electric") | D4: US316418332 | E4: 16934311 | F4: 21.07.2020 | G4: 20210027212 | H4: 28.01.2021 | I4: 2021 | J4: US | K4: OFFLINE TO ONLINE VEHICLE BOOKING | L4: G06Q 10/02; G06Q 50/30; G06K 7/10; G06K 19/06 | M4: OLA ELECTRIC MOBILITY PRIVATE LIMITED | N4: OLA ELECTRIC MOBILITY PRIVATE LIMITED | O4: exact-normalised | P4: 1 | S4: 19.10.2026 06:24:45
A5: Ola Electric | B5: 01_Ola_Electric_raw.xls | C5: PA:("Ola Electric") | D5: IN317292645 | E5: 201941029816 | F5: 23.07.2019 | G5: 201941029816 | H5: 29.01.2021 | I5: 2021 | J5: IN | K5: VEHICLE COMMUNICATION SYSTEM | L5: G06Q /; G06F /; H04N /; A42B /; H04B / | M5: OLA ELECTRIC MOBILITY PRIVATE LIMITED | N5: OLA ELECTRIC MOBILITY PRIVATE LIMITED | O5: exact-normalised | P5: 1 | S5: 19.10.2026 06:24:45
A6: Ola Electric | B6: 01_Ola_Electric_raw.xls | C6: PA:("Ola Electric") | D6: IN317292293 | E6: 201941029814 | F6: 23.07.2019 | G6: 201941029814 | H6: 29.01.2021 | I6: 2021 | J6: IN | K6: METHODS AND SYSTEMS FOR FACILITATING SAFETY AND SECURITY OF USERS | L6: G08B /; H04L /; G08B /; G08G /; G06Q / | M6: OLA ELECTRIC MOBILITY PRIVATE LIMITED | N6: OLA ELECTRIC MOBILITY PRIVATE LIMITED | O6: exact-normalised | P6: 1 | S6: 19.10.2026 06:24:45
A7: Ola Electric | B7: 01_Ola_Electric_raw.xls | C7: PA:("Ola Electric") | D7: IN317292292 | E7: 201941029811 | F7: 23.07.2019 | G7: 201941029811 | H7: 29.01.2021 | I7: 2021 | J7: IN | K7: OFFLINE TO ONLINE VEHICLE BOOKING | L7: G06Q /; H04W /; G06Q /; H04W /; H04W / | M7: OLA ELECTRIC MOBILITY PRIVATE LIMITED | N7: OLA ELECTRIC MOBILITY PRIVATE LIMITED | O7: exact-normalised | P7: 1 | S7: 19.10.2026 06:24:45
A8: Ola Electric | B8: 01_Ola_Electric_raw.xls | C8: PA:("Ola Electric") | D8: US320887047 | E8: 17027163 | F8: 21.09.2020 | G8: 20210086778 | H8: 25.03.2021 | I8: 2021 | J8: US | K8: IN-VEHICLE EMERGENCY DETECTION AND RESPONSE HANDLING | L8: B60W 40/08; B60W 60/00; B60Q 1/52; B60Q 1/50; G10L 15/22; G06F 3/01; A61B 5/00; H04W 4/90 | M8: OLA ELECTRIC MOBILITY PRIVATE LIMITED | N8: OLA ELECTRIC MOBILITY PRIVATE LIMITED | O8: exact-normalised | P8: 1 | S8: 19.10.2026 06:24:45
A9: Ola Electric | B9: 01_Ola_Electric_raw.xls | C9: PA:("Ola Electric") | D9: IN334771478 | E9: 201941029815 | F9: 23.09.2019 | G9: 201941029815 | H9: 16.07.2021 | I9: 2021 | J9: IN | K9: METHODS AND SYSTEMS FOR DETECTING AND COMMUNICATING EMERGENCY ALERTS TO ENTITIES | L9: H04W /; G08B /; H04W /; G08G /; G08B / | M9: OLA ELECTRIC MOBILITY PRIVATE LIMITED | N9: OLA ELECTRIC MOBILITY PRIVATE LIMITED | O9: exact-normalised | P9: 1 | S9: 19.10.2026 06:24:45
A10: Ola Electric | B10: 01_Ola_Electric_raw.xls | C10: PA:("Ola Electric") | D10: WO2021150108 | E10: PCT/NL2021/050034 | F10: 20.01.2021 | G10: WO/2021/150108 | H10: 29.07.2021 | I10: 2021 | J10: WO | K10: VEHICLE COMPRISING A BUDDY SPACE | L10: B62J 9/14; B62J 43/16; B62J 43/23; B62K 19/16; B62K 19/46 | M10: OLA ELECTRIC MOBILITY B.V. | N10: OLA ELECTRIC MOBILITY B.V. | O10: exact-normalised | P10: 1 | S10: 19.10.2026 06:24:45
A11: Ola Electric | B11: 01_Ola_Electric_raw.xls | C11: PA:("Ola Electric") | D11: WO2021150110 | E11: PCT/NL2021/050036 | F11: 21.01.2021 | G11: WO/2021/150110 | H11: 29.07.2021 | I11: 2021 | J11: WO | K11: BATTERY SYSTEM AND BATTERY MANAGEMENT METHOD | L11: H02J 7/00; B60L 58/00; H01M 10/44 | M11: OLA ELECTRIC MOBILITY B.V. | N11: OLA ELECTRIC MOBILITY B.V. | O11: exact-normalised | P11: 1 | S11: 19.10.2026 06:24:45
A12: Ola Electric | B12: 01_Ola_Electric_raw.xls | C12: PA:("Ola Electric") | D12: US338557605 | E12: 16910784 | F12: 24.06.2020 | G12: 20210309121 | H12: 07.10.2021 | I12: 2021 | J12: US | K12: Battery swapping to manage in-vehicle battery communication | L12: B60L 58/12; B60L 58/18; B60S 5/06; H01M 10/46; B60L 53/30 | M12: OLA ELECTRIC MOBILITY PRIVATE LIMITED | N12: OLA ELECTRIC MOBILITY PRIVATE LIMITED | O12: exact-normalised | P12: 1 | S12: 19.10.2026 06:24:45
A13: Ola Electric | B13: 01_Ola_Electric_raw.xls | C13: PA:("Ola Electric") | D13: US343549366 | E13: 17185607 | F13: 25.02.2021 | G13: 20210377030 | H13: 02.12.2021 | I13: 2021 | J13: US | K13: Offline authentication of batteries | L13: H04L 9/32; H01M 10/48; H04L 12/40 | M13: OLA ELECTRIC MOBILITY LIMITED | N13: OLA ELECTRIC MOBILITY LIMITED | O13: exact-normalised | P13: 1 | S13: 19.10.2026 06:24:45
... A82: Ola Electric | B82: 01_Ola_Electric_raw.xls | C82: PA:("Ola Electric") | D82: IN391018068 | E82: 202241003109 | F82: 19.01.2022 | G82: 202241003109 | H82: 27.01.2023 | I82: 2023 | J82: IN | K82: BATTERY PACK FOR VEHICLES | L82: H01M /; H01M /; H01M /; H01M /; B60L / | M82: OLA ELECTRIC MOBILITY PRIVATE LIMITED | N82: OLA ELECTRIC MOBILITY PRIVATE LIMITED | O82: exact-normalised | P82: 1 | S82: 19.10.2026 06:24:45
A83: Ola Electric | B83: 01_Ola_Electric_raw.xls | C83: PA:("Ola Electric") | D83: WO2023007515 | E83: PCT/IN2022/050675 | F83: 26.07.2022 | G83: WO/2023/007515 | H83: 02.02.2023 | I83: 2023 | J83: WO | K83: AUTOMATIC LOCKING AND UNLOCKING OF VEHICLES | L83: B60R 25/01; B60R 25/30; G07C 5/00 | M83: OLA ELECTRIC MOBILITY PRIVATE LIMITED; AGGARWAL, Bhavish; MAJJI, Shravanthi; AGARWAL, Gaurav; JAIN, Nishit; JAYARAMAN, Vijayanand | N83: OLA ELECTRIC MOBILITY PRIVATE LIMITED | O83: exact-normalised | P83: 1 | Q83: AGGARWAL, Bhavish; MAJJI, Shravanthi; AGARWAL, Gaurav; JAIN, Nishit; JAYARAMAN, Vijayanand | R83: other parties listed | S83: 19.10.2026 06:24:45
A84: Ola Electric | B84: 01_Ola_Electric_raw.xls | C84: PA:("Ola Electric") | D84: IN391899418 | E84: 202241006404 | F84: 07.02.2022 | G84: 202241006404 | H84: 10.02.2023 | I84: 2023 | J84: IN | K84: CATHODE SLURRY FOR ALKALI-ION BATTERIES AND A METHOD FOR ITS PREPARATION | L84: H01M /; H01M /; H01M /; H01M /; H01M / | M84: OLA ELECTRIC MOBILITY PRIVATE LIMITED | N84: OLA ELECTRIC MOBILITY PRIVATE LIMITED | O84: exact-normalised | P84: 1 | S84: 19.10.2026 06:24:45
A85: Ola Electric | B85: 01_Ola_Electric_raw.xls | C85: PA:("Ola Electric") | D85: IN392341047 | E85: 202141062206 | F85: 31.12.2021 | G85: 202141062206 | H85: 17.02.2023 | I85: 2023 | J85: IN | K85: SOLID ELECTROLYTE MEMBRANE AND PREPARATION METHODS THEREOF | L85: A61K /; B24B /; B29C /; H01M /; B29C / | M85: OLA ELECTRIC MOBILITY PRIVATE LIMITED | N85: OLA ELECTRIC MOBILITY PRIVATE LIMITED | O85: exact-normalised | P85: 1 | S85: 19.10.2026 06:24:45
A86: Ola Electric | B86: 01_Ola_Electric_raw.xls | C86: PA:("Ola Electric") | D86: IN392341646 | E86: 202341007419 | F86: 06.02.2023 | G86: 202341007419 | H86: 17.02.2023 | I86: 2023 | J86: IN | K86: A SYSTEM FOR SUPPLYING SUPPLEMENTARY ELECTRICAL ENERGY TO AN ELECTRIC VEHICLE AND A METHOD THEREOF | L86: B60K 6/28; B60L 50/40; B60L 50/60; B60L 53/00; B60L 53/20; H02J 7/00 | M86: OLA ELECTRIC MOBILITY PRIVATE LIMITED | N86: OLA ELECTRIC MOBILITY PRIVATE LIMITED | O86: exact-normalised | P86: 1 | S86: 19.10.2026 06:24:45
A87: Ola Electric | B87: 01_Ola_Electric_raw.xls | C87: PA:("Ola Electric") | D87: IN392341617 | E87: 202341002281 | F87: 11.01.2023 | G87: 202341002281 | H87: 17.02.2023 | I87: 2023 | J87: IN | K87: A CONTROL UNIT ASSEMBLY | L87: B60R 16/02; H01R 13/52; H05K 5/06 | M87: OLA ELECTRIC MOBILITY PRIVATE LIMITED | N87: OLA ELECTRIC MOBILITY PRIVATE LIMITED | O87: exact-normalised | P87: 1 | S87: 19.10.2026 06:24:45
A88: Ola Electric | B88: 01_Ola_Electric_raw.xls | C88: PA:("Ola Electric") | D88: IN393021931 | E88: 202341006643 | F88: 01.02.2023 | G88: 202341006643 | H88: 24.02.2023 | I88: 2023 | J88: IN | K88: EFFICIENCY OF A CHARGER AND WALL-TO-WHEEL EFFICIENCY OF AN ELECTRIC VEHICLE | L88: B60L 53/60; B60L 53/66; B60L 58/00; B60L 58/10 | M88: OLA ELECTRIC MOBILITY PRIVATE LIMITED | N88: OLA ELECTRIC MOBILITY PRIVATE LIMITED | O88: exact-normalised | P88: 1 | S88: 19.10.2026 06:24:45
A89: Ola Electric | B89: 01_Ola_Electric_raw.xls | C89: PA:("Ola Electric") | D89: IN393021987 | E89: 202341010177 | F89: 15.02.2023 | G89: 202341010177 | H89: 24.02.2023 | I89: 2023 | J89: IN | K89: A DERATION SYSTEM FOR AN ELECTRIC VEHICLE | L89: B60L 15/20; B60L 3/08; B60W 10/08 | M89: OLA ELECTRIC MOBILITY PRIVATE LIMITED | N89: OLA ELECTRIC MOBILITY PRIVATE LIMITED | O89: exact-normalised | P89: 1 | S89: 19.10.2026 06:24:45
A90: Ola Electric | B90: 01_Ola_Electric_raw.xls | C90: PA:("Ola Electric") | D90: IN393021901 | E90: 202341005162 | F90: 25.01.2023 | G90: 202341005162 | H90: 24.02.2023 | I90: 2023 | J90: IN | K90: A SYSTEM AND METHOD FOR CONTROLLING THE TINTING OF WINDOW PANES OF A VEHICLE | L90: B60J 3/00; B60J 3/02; B60J 3/04; G02F 1/00 | M90: OLA ELECTRIC MOBILITY PRIVATE LIMITED | N90: OLA ELECTRIC MOBILITY PRIVATE LIMITED | O90: exact-normalised | P90: 1 | S90: 19.10.2026 06:24:45
A91: Ola Electric | B91: 01_Ola_Electric_raw.xls | C91: PA:("Ola Electric") | D91: IN393021427 | E91: 202341007186 | F91: 03.02.2023 | G91: 202341007186 | H91: 24.02.2023 | I91: 2023 | J91: IN | K91: A SYSTEM AND A METHOD FOR CONTROLLING THE TINTING OF WINDOW PANES | L91: E06B 9/24; G02F 1/00; G02F 1/23; G05B 13/00 | M91: OLA ELECTRIC MOBILITY PRIVATE LIMITED | N91: OLA ELECTRIC MOBILITY PRIVATE LIMITED | O91: exact-normalised | P91: 1 | S91: 19.10.2026 06:24:45
A92: Ola Electric | B92: 01_Ola_Electric_raw.xls | C92: PA:("Ola Electric") | D92: IN394088732 | E92: 202341017119 | F92: 14.03.2023 | G92: 202341017119 | H92: 17.03.2023 | I92: 2023 | J92: IN | K92: AN ELECTRIC CURRENT MEASURING SYSTEM AND A METHOD THEREOF | L92: G01R 19/00; G01R 19/10; G01R 19/25 | M92: OLA ELECTRIC MOBILITY PRIVATE LIMITED | N92: OLA ELECTRIC MOBILITY PRIVATE LIMITED | O92: exact-normalised | P92: 1 | S92: 19.10.2026 06:24:45
A93: Ola Electric | B93: 01_Ola_Electric_raw.xls | C93: PA:("Ola Electric") | D93: IN394088675 | E93: 202341013892 | F93: 01.03.2023 | G93: 202341013892 | H93: 17.03.2023 | I93: 2023 | J93: IN | K93: CURRENT COLLECTOR PLATES FOR BATTERIES | L93: H01M 10/04; H01M 10/643; H01M 10/655; H01M 4/04; H01M 4/64 | M93: OLA ELECTRIC MOBILITY PRIVATE LIMITED | N93: OLA ELECTRIC MOBILITY PRIVATE LIMITED | O93: exact-normalised | P93: 1 | S93: 19.10.2026 06:24:45
A94: Ola Electric | B94: 01_Ola_Electric_raw.xls | C94: PA:("Ola Electric") | D94: IN394087619 | E94: 202341011759 | F94: 21.02.2023 | G94: 202341011759 | H94: 17.03.2023 | I94: 2023 | J94: IN | K94: PERSONALIZING TORQUE PROFILES OF AN ELECTRIC VEHICLE | L94: B60H /; B60L /; B60L /; B60L /; B62K / | M94: OLA ELECTRIC MOBILITY PRIVATE LIMITED | N94: OLA ELECTRIC MOBILITY PRIVATE LIMITED | O94: exact-normalised | P94: 1 | S94: 19.10.2026 06:24:45
A95: Ola Electric | B95: 01_Ola_Electric_raw.xls | C95: PA:("Ola Electric") | D95: IN394088733 | E95: 202341017120 | F95: 14.03.2023 | G95: 202341017120 | H95: 17.03.2023 | I95: 2023 | J95: IN | K95: A SYSTEM AND A METHOD FOR REDUCING THE BRAKING DISTANCE OF A VEHICLE | L95: B60T 13/66; B60T 7/12; B60T 8/17; B60T 8/32; B60T 8/34; B60T 8/58; B60T 8/60; B60W 30/09 | M95: OLA ELECTRIC MOBILITY PRIVATE LIMITED | N95: OLA ELECTRIC MOBILITY PRIVATE LIMITED | O95: exact-normalised | P95: 1 | S95: 19.10.2026 06:24:45
... A267: Ola Electric | B267: 01_Ola_Electric_raw.xls | C267: PA:("Ola Electric") | D267: WO2026176467 | E267: PCT/IN2026/050279 | F267: 18.02.2026 | G267: WO/2026/176467 | H267: 27.08.2026 | I267: 2026 | J267: WO | K267: A CATHODE COMPOSITE, A LITHIUM-ION BATTERY AND PROCESSES THEREOF | L267: C25B 11/04; H01M 4/02; H01M 4/04; H01M 4/485; H01M 4/505; H01M 4/58; H01M 4/583; H01M 4/62; H01M 4/133 | M267: OLA ELECTRIC MOBILITY LIMITED | N267: OLA ELECTRIC MOBILITY LIMITED | O267: exact-normalised | P267: 1 | S267: 19.10.2026 06:24:45
A268: Ola Electric | B268: 01_Ola_Electric_raw.xls | C268: PA:("Ola Electric") | D268: DE485893907 | E268: 112023007059 | G268: 112023007059 | H268: 03.09.2026 | I268: 2026 | J268: DE | K268: VERFAHREN ZUR HERSTELLUNG EINER ELEKTRODE | L268: H01M 4/139; H01M 4/62; H01M 4/36; H01M 4/133 | M268: OLA ELECTRIC MOBILITY LIMITED | N268: OLA ELECTRIC MOBILITY LIMITED | O268: exact-normalised | P268: 1 | S268: 19.10.2026 06:24:45
A269: Ola Electric | B269: 01_Ola_Electric_raw.xls | C269: PA:("Ola Electric") | D269: WO2026185889 | E269: PCT/IN2026/050394 | F269: 05.03.2026 | G269: WO/2026/185889 | H269: 10.09.2026 | I269: 2026 | J269: WO | K269: A CATHODE ACTIVE MATERIAL AND PROCESS THEREOF | L269: H01M 4/505; H01M 4/525; H01M 10/052; H01M 4/36; H01M 4/131; H01M 4/62; H01M 4/02 | M269: OLA ELECTRIC MOBILITY LIMITED | N269: OLA ELECTRIC MOBILITY LIMITED | O269: exact-normalised | P269: 1 | S269: 19.10.2026 06:24:45
A270: Ola Electric | B270: 01_Ola_Electric_raw.xls | C270: PA:("Ola Electric") | D270: WO2026215915 | E270: PCT/IN2026/050639 | F270: 07.04.2026 | G270: WO/2026/215915 | H270: 15.10.2026 | I270: 2026 | J270: WO | K270: AN ACTIVE MATERIAL, AN ELECTRODE COMPOSITE AND PREPARATIONS THEREOF | L270: H01M 4/134; H01M 4/48; H01M 4/36; H01M 4/38; H01M 4/62 | M270: OLA ELECTRIC MOBILITY LIMITED | N270: OLA ELECTRIC MOBILITY LIMITED | O270: exact-normalised | P270: 1 | S270: 19.10.2026 06:24:45
A271: Ather Energy | B271: 03_Ather_Energy_raw.xls | C271: PA:("Ather Energy") | D271: IN453983529 | E271: 202341065935 | F271: 30.09.2023 | G271: 202341065935 | H271: 04.04.2025 | I271: 2025 | J271: IN | K271: ELECTRIC POWER SUPPLY DEVICE AND METHOD OF OPERATION THEREOF | L271: B60L 53/00; B60L 53/10; B60L 53/60; H02J 7/02; H02J 7/06; H02M 1/00; H02M 1/10; H02M 7/219 | M271: Ather Energy Limited | N271: Ather Energy Limited | O271: exact-normalised | P271: 1 | S271: 19.10.2026 06:19:49
A272: Ather Energy | B272: 03_Ather_Energy_raw.xls | C272: PA:("Ather Energy") | D272: WO2026069090 | E272: PCT/IB2025/059436 | F272: 19.09.2025 | G272: WO/2026/069090 | H272: 02.04.2026 | I272: 2026 | J272: WO | K272: SYSTEMS AND METHODS FOR THERMAL MANAGEMENT OF A BATTERY PACK | L272: H01M 10/635; H01M 10/613; H02J 7/00 | M272: ATHER ENERGY LIMITED | N272: ATHER ENERGY LIMITED | O272: exact-normalised | P272: 1 | S272: 19.10.2026 06:19:49
A273: Ather Energy | B273: 03_Ather_Energy_raw.xls | C273: PA:("Ather Energy") | D273: WO2025088588 | E273: PCT/IB2024/060557 | F273: 26.10.2024 | G273: WO/2025/088588 | H273: 01.05.2025 | I273: 2025 | J273: WO | K273: METHOD AND SYSTEM FOR BALANCING BATTERY PACK OF ELECTRIC VEHICLE | L273: B60L 58/22; H02J 7/00; H01M 10/42; G01R 31/367; G01R 31/382; G01R 31/396 | M273: ATHER ENERGY LIMITED | N273: ATHER ENERGY LIMITED | O273: exact-normalised | P273: 1 | S273: 19.10.2026 06:19:49
A274: Ather Energy | B274: 03_Ather_Energy_raw.xls | C274: PA:("Ather Energy") | D274: ID484164954 | E274: P00202605069 | F274: 26.10.2024 | G274: 2026/04336 | H274: 25.05.2026 | I274: 2026 | J274: ID | K274: METHOD AND SYSTEM FOR BALANCING BATTERY PACK OF ELECTRIC VEHICLE | L274: H01M 10/42; H02J 7/00; B60L 58/22; G01R 31/396; G01R 31/382; G01R 31/367 | M274: ATHER ENERGY LIMITED | N274: ATHER ENERGY LIMITED | O274: exact-normalised | P274: 1 | S274: 19.10.2026 06:19:49
A275: Ather Energy | B275: 03_Ather_Energy_raw.xls | C275: PA:("Ather Energy") | D275: WO2025181534 | E275: PCT/IB2024/060586 | F275: 28.10.2024 | G275: WO/2025/181534 | H275: 04.09.2025 | I275: 2025 | J275: WO | K275: APPARATUS AND METHOD FOR MANAGING A CHARGING CONNECTOR | L275: B60L 53/16; H01R 13/639 | M275: ATHER ENERGY LIMITED | N275: ATHER ENERGY LIMITED | O275: exact-normalised | P275: 1 | S275: 19.10.2026 06:19:49
A276: Ather Energy | B276: 03_Ather_Energy_raw.xls | C276: PA:("Ather Energy") | D276: WO2026210211 | E276: PCT/IB2025/059441 | F276: 19.09.2025 | G276: WO/2026/210211 | H276: 08.10.2026 | I276: 2026 | J276: WO | K276: SYSTEM AND METHOD FOR CONTROLLING A POWER DISTRIBUTION UNIT IN A VEHICLE | L276: H04W 4/40; B60L 53/14; B60R 16/033; H02J 76/00 | M276: ATHER ENERGY LIMITED | N276: ATHER ENERGY LIMITED | O276: exact-normalised | P276: 1 | S276: 19.10.2026 06:19:49
A277: Ather Energy | B277: 03_Ather_Energy_raw.xls | C277: PA:("Ather Energy") | D277: WO2025094003 | E277: PCT/IB2024/060475 | F277: 24.10.2024 | G277: WO/2025/094003 | H277: 08.05.2025 | I277: 2025 | J277: WO | K277: A SYSTEM FOR WEAR DETECTION OF A HELMET AND A METHOD THEROF | L277: H04B 1/3827; A42B 3/04; G08B 21/18 | M277: ATHER ENERGY LIMITED | N277: ATHER ENERGY LIMITED | O277: exact-normalised | P277: 1 | S277: 19.10.2026 06:19:49
A278: Ather Energy | B278: 03_Ather_Energy_raw.xls | C278: PA:("Ather Energy") | D278: WO2026083159 | E278: PCT/IB2025/059262 | F278: 16.09.2025 | G278: WO/2026/083159 | H278: 23.04.2026 | I278: 2026 | J278: WO | K278: METHOD AND SYSTEM FOR THERMAL MANAGEMENT OF A VEHICLE | L278: B60L 58/24; H01M 10/625 | M278: ATHER ENERGY LIMITED | N278: ATHER ENERGY LIMITED | O278: exact-normalised | P278: 1 | S278: 19.10.2026 06:19:49
A279: Ather Energy | B279: 03_Ather_Energy_raw.xls | C279: PA:("Ather Energy") | D279: WO2026146322 | E279: PCT/IB2025/059425 | F279: 01.12.2025 | G279: WO/2026/146322 | H279: 09.07.2026 | I279: 2026 | J279: WO | K279: A SYSTEM TO CONTROL TRACTION OF A VEHICLE AND METHODS THEREOF | L279: B60W 30/18; B60K 28/16; B60T 8/175 | M279: ATHER ENERGY LIMITED | N279: ATHER ENERGY LIMITED | O279: exact-normalised | P279: 1 | S279: 19.10.2026 06:19:49
...

Sheet Rejected_Rows
A1: Searched for | B1: Source file | C1: Query | D1: Application Id | E1: Publication Number | F1: Publication Date | G1: Country | H1: Title | I1: Applicants (as in WIPO) | J1: Best similarity | K1: Reason
A2: Ola Electric | B2: 01_Ola_Electric_raw.xls | C2: PA:("Ola Electric") | D2: CN203423306 | E2: 107022889 | F2: 08.08.2017 | G2: CN | H2: Double-channel cyclic heating system of clothing care machine | I2: NANTONG OLA ELECTRIC APPLIANCE CO., LTD. | J2: 0.59 | K2: applicant name does not match the startup's registered name
A3: Ola Electric | B3: 01_Ola_Electric_raw.xls | C3: PA:("Ola Electric") | D3: CN203436952 | E3: 107034650 | F3: 11.08.2017 | G3: CN | H3: Dry cleaning leveling structure of clothes nursing machine | I3: NANTONG OLA ELECTRIC APPLIANCE CO., LTD. | J3: 0.59 | K3: applicant name does not match the startup's registered name

Sheet Alias_Table
A1: Startup | B1: Registered-name alias searched/matched | C1: Normalised form
A2: Ola Electric | B2: Ola Electric Mobility | C2: ola electric mobility
A3: Ather Energy | B3: Ather Energy | C3: ather energy
A4: River | B4: River Mobility | C4: river mobility
A5: SUN Mobility | B5: SUN Mobility | C5: sun mobility
A6: Ultraviolette Automotive | B6: Ultraviolette Automotive | C6: ultraviolette automotive
A7: Matter | B7: Matter Motor Works | C7: matter motor works
A8: Ecozen Solutions | B8: Ecozen Solutions | C8: ecozen solutions
A9: Smartron | B9: Smartron India | C9: smartron india
A10: Carbon Clean Solutions | B10: Carbon Clean Solutions | C10: carbon clean solutions
A11: Chakr Innovation | B11: Chakr Innovation | C11: chakr innovation

Sheet File_Checks
A1: File | B1: Searched for | C1: Query in file | D1: Rows in file | E1: Matched | F1: Rejected | G1: Duplicate publication numbers
A2: 01_Ola_Electric_raw.xls | B2: Ola Electric | C2: PA:("Ola Electric") | D2: 271 | E2: 269 | F2: 2 | G2: 0
A3: 03_Ather_Energy_raw.xls | B3: Ather Energy | C3: PA:("Ather Energy") | D3: 100 | E3: 100 | F3: 0 | G3: 0
A4: 07_River_Mobility_raw.xls | B4: River | C4: PA:("River mobility") | D4: 20 | E4: 20 | F4: 0 | G4: 0
A5: 10_Sun_Mobility_raw.xls | B5: SUN Mobility | C5: PA:("SUN Mobility") | D5: 87 | E5: 87 | F5: 0 | G5: 0
A6: 11_Ultraviolette_Automotive_raw.xls | B6: Ultraviolette Automotive | C6: PA:("Ultraviolette Automotive") | D6: 43 | E6: 43 | F6: 0 | G6: 0
A7: 15_Matter_raw.xls | B7: Matter | C7: PA:("Matter Motor Works") | D7: 65 | E7: 65 | F7: 0 | G7: 0
A8: 16_Ecozen_Solutions_raw.xls | B8: Ecozen Solutions | C8: PA:("Ecozen Solutions") | D8: 1 | E8: 1 | F8: 0 | G8: 0
A9: 17_smartron_India_raw.xls | B9: Smartron | C9: PA:("Smartron India") | D9: 28 | E9: 28 | F9: 0 | G9: 0
A10: 18_CarbonClean_Solutions_raw.xls | B10: Carbon Clean Solutions | C10: PA:("Carbon Clean Solutions") | D10: 104 | E10: 104 | F10: 0 | G10: 4
A11: 19_Chakr_Innovation_raw.xls | B11: Chakr Innovation | C11: PA:("Chakr Innovation") | D11: 13 | E11: 13 | F11: 0 | G11: 0
A13: Rows in file = Matched + Rejected for every file. Compare 'Rows in file' with the count in WIPO_Search_Log.
